
[2015-12-07 14:41:23,100] [ERROR] views : [ColumnView]访问专栏不存在: [linux]
[2015-12-08 14:32:01,955] [ERROR] views : [CategoryView]此分类不存在:[uncategorized]
[2015-12-08 15:05:23,634] [ERROR] views : [CategoryView]此分类不存在:[uncategorized]
[2015-12-09 11:14:24,257] [ERROR] views : [ColumnView]访问专栏不存在: [life]
[2015-12-09 11:16:33,482] [ERROR] views : [ColumnView]访问专栏不存在: [life]
[2015-12-09 11:16:41,028] [ERROR] views : [ColumnView]访问专栏不存在: [linux]
[2015-12-09 14:20:30,905] [ERROR] views : [ColumnView]访问专栏不存在: [life]
[2015-12-09 14:20:42,816] [ERROR] views : [ColumnView]访问专栏不存在: [linux]
[2015-12-09 14:22:10,770] [ERROR] views : [ColumnView]访问专栏不存在: [linux]
[2015-12-09 16:19:10,767] [ERROR] views : [UserControl]用户注册邮件发送失败:[admin1]/[121736729@qq.com]
[2015-12-09 16:23:06,421] [ERROR] views : [UserControl]用户注册邮件发送失败:[admin1]/[121736729@qq.com]
[2015-12-09 16:23:15,125] [ERROR] views : [UserControl]用户注册邮件发送失败:[admin1]/[121736724@qq.com]
[2015-12-09 16:25:02,779] [ERROR] views : [UserControl]用户注册邮件发送失败:[admin1]/[694366594@qq.com]
[2015-12-09 16:32:40,886] [ERROR] views : [UserControl]用户注册邮件发送失败:[rootadmin]/[694366594@qq.com]
[2015-12-09 16:38:17,856] [ERROR] views : [UserControl]用户注册邮件发送失败:[rootadmin]/[694366594@qq.com]
[2015-12-09 16:41:10,146] [ERROR] views : [UserControl]用户注册邮件发送失败:[rootadmin]/[694366594@qq.com]
[2015-12-09 16:42:03,990] [ERROR] views : [UserControl]用户注册邮件发送失败:[rootadmin]/[694366594@qq.com]
[2015-12-10 01:07:55,185] [ERROR] views : [CategoryView]此分类不存在:[uncategorized]
[2015-12-11 18:01:36,025] [ERROR] base : Internal Server Error: /article/qiangpiao.html
Traceback (most recent call last):
  File "/usr/local/lib/python2.7/site-packages/Django-1.8.4-py2.7.egg/django/core/handlers/base.py", line 132, in get_response
    response = wrapped_callback(request, *callback_args, **callback_kwargs)
  File "/usr/local/lib/python2.7/site-packages/Django-1.8.4-py2.7.egg/django/views/generic/base.py", line 71, in view
    return self.dispatch(request, *args, **kwargs)
  File "/usr/local/lib/python2.7/site-packages/Django-1.8.4-py2.7.egg/django/views/generic/base.py", line 89, in dispatch
    return handler(request, *args, **kwargs)
  File "./blog/views.py", line 91, in get
    article = self.queryset.get(en_title=en_title)
  File "/usr/local/lib/python2.7/site-packages/Django-1.8.4-py2.7.egg/django/db/models/query.py", line 338, in get
    (self.model._meta.object_name, num)
MultipleObjectsReturned: get() returned more than one Article -- it returned 2!
[2015-12-11 18:01:36,025] [ERROR] base : Internal Server Error: /article/qiangpiao.html
Traceback (most recent call last):
  File "/usr/local/lib/python2.7/site-packages/Django-1.8.4-py2.7.egg/django/core/handlers/base.py", line 132, in get_response
    response = wrapped_callback(request, *callback_args, **callback_kwargs)
  File "/usr/local/lib/python2.7/site-packages/Django-1.8.4-py2.7.egg/django/views/generic/base.py", line 71, in view
    return self.dispatch(request, *args, **kwargs)
  File "/usr/local/lib/python2.7/site-packages/Django-1.8.4-py2.7.egg/django/views/generic/base.py", line 89, in dispatch
    return handler(request, *args, **kwargs)
  File "./blog/views.py", line 91, in get
    article = self.queryset.get(en_title=en_title)
  File "/usr/local/lib/python2.7/site-packages/Django-1.8.4-py2.7.egg/django/db/models/query.py", line 338, in get
    (self.model._meta.object_name, num)
MultipleObjectsReturned: get() returned more than one Article -- it returned 2!
[2015-12-11 18:01:40,246] [ERROR] base : Internal Server Error: /article/qiangpiao.html
Traceback (most recent call last):
  File "/usr/local/lib/python2.7/site-packages/Django-1.8.4-py2.7.egg/django/core/handlers/base.py", line 132, in get_response
    response = wrapped_callback(request, *callback_args, **callback_kwargs)
  File "/usr/local/lib/python2.7/site-packages/Django-1.8.4-py2.7.egg/django/views/generic/base.py", line 71, in view
    return self.dispatch(request, *args, **kwargs)
  File "/usr/local/lib/python2.7/site-packages/Django-1.8.4-py2.7.egg/django/views/generic/base.py", line 89, in dispatch
    return handler(request, *args, **kwargs)
  File "./blog/views.py", line 91, in get
    article = self.queryset.get(en_title=en_title)
  File "/usr/local/lib/python2.7/site-packages/Django-1.8.4-py2.7.egg/django/db/models/query.py", line 338, in get
    (self.model._meta.object_name, num)
MultipleObjectsReturned: get() returned more than one Article -- it returned 2!
[2015-12-11 18:01:40,246] [ERROR] base : Internal Server Error: /article/qiangpiao.html
Traceback (most recent call last):
  File "/usr/local/lib/python2.7/site-packages/Django-1.8.4-py2.7.egg/django/core/handlers/base.py", line 132, in get_response
    response = wrapped_callback(request, *callback_args, **callback_kwargs)
  File "/usr/local/lib/python2.7/site-packages/Django-1.8.4-py2.7.egg/django/views/generic/base.py", line 71, in view
    return self.dispatch(request, *args, **kwargs)
  File "/usr/local/lib/python2.7/site-packages/Django-1.8.4-py2.7.egg/django/views/generic/base.py", line 89, in dispatch
    return handler(request, *args, **kwargs)
  File "./blog/views.py", line 91, in get
    article = self.queryset.get(en_title=en_title)
  File "/usr/local/lib/python2.7/site-packages/Django-1.8.4-py2.7.egg/django/db/models/query.py", line 338, in get
    (self.model._meta.object_name, num)
MultipleObjectsReturned: get() returned more than one Article -- it returned 2!
[2015-12-11 18:01:53,600] [ERROR] base : Internal Server Error: /article/qiangpiao.html
Traceback (most recent call last):
  File "/usr/local/lib/python2.7/site-packages/Django-1.8.4-py2.7.egg/django/core/handlers/base.py", line 132, in get_response
    response = wrapped_callback(request, *callback_args, **callback_kwargs)
  File "/usr/local/lib/python2.7/site-packages/Django-1.8.4-py2.7.egg/django/views/generic/base.py", line 71, in view
    return self.dispatch(request, *args, **kwargs)
  File "/usr/local/lib/python2.7/site-packages/Django-1.8.4-py2.7.egg/django/views/generic/base.py", line 89, in dispatch
    return handler(request, *args, **kwargs)
  File "./blog/views.py", line 91, in get
    article = self.queryset.get(en_title=en_title)
  File "/usr/local/lib/python2.7/site-packages/Django-1.8.4-py2.7.egg/django/db/models/query.py", line 338, in get
    (self.model._meta.object_name, num)
MultipleObjectsReturned: get() returned more than one Article -- it returned 2!
[2015-12-11 18:01:53,600] [ERROR] base : Internal Server Error: /article/qiangpiao.html
Traceback (most recent call last):
  File "/usr/local/lib/python2.7/site-packages/Django-1.8.4-py2.7.egg/django/core/handlers/base.py", line 132, in get_response
    response = wrapped_callback(request, *callback_args, **callback_kwargs)
  File "/usr/local/lib/python2.7/site-packages/Django-1.8.4-py2.7.egg/django/views/generic/base.py", line 71, in view
    return self.dispatch(request, *args, **kwargs)
  File "/usr/local/lib/python2.7/site-packages/Django-1.8.4-py2.7.egg/django/views/generic/base.py", line 89, in dispatch
    return handler(request, *args, **kwargs)
  File "./blog/views.py", line 91, in get
    article = self.queryset.get(en_title=en_title)
  File "/usr/local/lib/python2.7/site-packages/Django-1.8.4-py2.7.egg/django/db/models/query.py", line 338, in get
    (self.model._meta.object_name, num)
MultipleObjectsReturned: get() returned more than one Article -- it returned 2!
[2015-12-11 18:01:55,422] [ERROR] base : Internal Server Error: /article/qiangpiao.html
Traceback (most recent call last):
  File "/usr/local/lib/python2.7/site-packages/Django-1.8.4-py2.7.egg/django/core/handlers/base.py", line 132, in get_response
    response = wrapped_callback(request, *callback_args, **callback_kwargs)
  File "/usr/local/lib/python2.7/site-packages/Django-1.8.4-py2.7.egg/django/views/generic/base.py", line 71, in view
    return self.dispatch(request, *args, **kwargs)
  File "/usr/local/lib/python2.7/site-packages/Django-1.8.4-py2.7.egg/django/views/generic/base.py", line 89, in dispatch
    return handler(request, *args, **kwargs)
  File "./blog/views.py", line 91, in get
    article = self.queryset.get(en_title=en_title)
  File "/usr/local/lib/python2.7/site-packages/Django-1.8.4-py2.7.egg/django/db/models/query.py", line 338, in get
    (self.model._meta.object_name, num)
MultipleObjectsReturned: get() returned more than one Article -- it returned 2!
[2015-12-11 18:01:55,422] [ERROR] base : Internal Server Error: /article/qiangpiao.html
Traceback (most recent call last):
  File "/usr/local/lib/python2.7/site-packages/Django-1.8.4-py2.7.egg/django/core/handlers/base.py", line 132, in get_response
    response = wrapped_callback(request, *callback_args, **callback_kwargs)
  File "/usr/local/lib/python2.7/site-packages/Django-1.8.4-py2.7.egg/django/views/generic/base.py", line 71, in view
    return self.dispatch(request, *args, **kwargs)
  File "/usr/local/lib/python2.7/site-packages/Django-1.8.4-py2.7.egg/django/views/generic/base.py", line 89, in dispatch
    return handler(request, *args, **kwargs)
  File "./blog/views.py", line 91, in get
    article = self.queryset.get(en_title=en_title)
  File "/usr/local/lib/python2.7/site-packages/Django-1.8.4-py2.7.egg/django/db/models/query.py", line 338, in get
    (self.model._meta.object_name, num)
MultipleObjectsReturned: get() returned more than one Article -- it returned 2!
[2015-12-13 00:04:30,337] [ERROR] views : [CategoryView]此分类不存在:[tomcat]
[2015-12-13 01:34:03,785] [ERROR] views : [CategoryView]此分类不存在:[shell]
